Workbook

Sheet INVENTORY
K1: =Units_Data!A12 -> B1-GF-10
A2: Lookup 1 | K2: =Units_Data!A13 -> B1-GF-11
A3: Select Unit No. | B3: B1-GF-37 | K3: =Units_Data!A14 -> B1-GF-12
A4: Unit Type | B4: {=IFERROR(INDEX(Units_Data!B$3:B$65,MATCH(B3,Units_Data!$A$3:$A$65,0)),"")} -> F&B | K4: =Units_Data!A15 -> B1-GF-13
A5: Floor | B5: {=IFERROR(INDEX(Units_Data!C$3:C$65,MATCH(B3,Units_Data!$A$3:$A$65,0)),"")} -> Ground | K5: =Units_Data!A16 -> B1-GF-14
A6: INDOOR Area (m²) | B6: {=IFERROR(INDEX(Units_Data!D$3:D$65,MATCH(B3,Units_Data!$A$3:$A$65,0)),"")} -> 281.6275 | K6: =Units_Data!A17 -> B1-GF-15
A7: OUTDOOR AREA ( m2) | B7: {=IFERROR(INDEX(Units_Data!G$3:G$65,MATCH(B3,Units_Data!$A$3:$A$65,0)),"")} -> 244.1
A8: Total UNIT Price | B8: {=IFERROR(INDEX(Units_Data!J$3:J$65,MATCH(B3,Units_Data!$A$3:$A$65,0)),"")} -> 830818.25 | K8: =Units_Data!A19 -> B1-GF-17
A9: Status | B9: {=IFERROR(INDEX(Units_Data!M$3:M$65,MATCH(B3,Units_Data!$A$3:$A$65,0)),"")} | K9: =Units_Data!A22 -> B1-GF-20
A10: Notes | B10: {=IFERROR(INDEX(Units_Data!N$3:N$65,MATCH(B3,Units_Data!$A$3:$A$65,0)),"")} | K10: =Units_Data!A23 -> B1-GF-21
A11: DISCOUNT PERCENTAGE | B11: 0
A12: TOTAL AFTER DISCOUNT | B12: =B8-(B8*B11) -> 830818.25 | K12: =Units_Data!A24 -> B1-GF-22
K14: =Units_Data!#REF! -> #ERROR!
K15: =Units_Data!#REF! -> #ERROR!
K16: =Units_Data!#REF! -> #ERROR!
K17: =Units_Data!#REF! -> #ERROR!
K18: =Units_Data!#REF! -> #ERROR!
K19: =Units_Data!#REF! -> #ERROR!
K20: =Units_Data!#REF! -> #ERROR!
K21: =Units_Data!#REF! -> #ERROR!
K22: =Units_Data!#REF! -> #ERROR!
K23: =Units_Data!#REF! -> #ERROR!
K24: =Units_Data!#REF! -> #ERROR!
K25: =Units_Data!#REF! -> #ERROR!
... K925: =Units_Data!#REF! -> #ERROR!

Sheet Units_Data
A1: Units Database
A2: Unit No. | B2: Unit Type | C2: Floor | D2: INDOOR Area (m²) | E2: Original Price/m² | F2: Original INDOOR Total Price | G2: OUTDOOR AREA | H2: ORIGINAL PRICE / m² | I2: ORIGINAL OUTDOOR TOTAL PRICE | J2: TOTAL UNIT PRICE | K2: Actual Price/m² | L2: Actual Total Price | M2: Status | N2: Notes
A3: B1-GF-01 | B3: Luxury Fashion | C3: Ground | D3: 377.7 | E3: 2000 | F3: =IF(OR(D3="",E3=""),"",D3*E3) -> 755400 | G3: 779.6 | H3: 750 | I3: =H3*G3 -> 584700 | J3: =I3+F3 -> 1340100 | K3: 1500 | L3: =IF(OR(D3="",K3=""),"",D3*K3) -> 566550 | M3: Negotiated | N3: Sample
A4: B1-GF-02 | B4: Luxury Fashion | C4: Ground | D4: 139.384 | E4: 3000 | F4: =IF(OR(D4="",E4=""),"",D4*E4) -> 418152 | G4: 53.42 | H4: 750 | I4: =H4*G4 -> 40065 | J4: =I4+F4 -> 458217 | K4: 2200 | L4: =IF(OR(D4="",K4=""),"",D4*K4) -> 306644.8 | M4: Available
A5: B1-GF-03 | B5: Luxury Fashion | C5: Ground | D5: 183.5533 | E5: 3000 | F5: =IF(OR(D5="",E5=""),"",D5*E5) -> 550659.9 | G5: 51.36 | H5: 750 | I5: =H5*G5 -> 38520 | J5: =I5+F5 -> 589179.9 | K5: 1800 | L5: =IF(OR(D5="",K5=""),"",D5*K5) -> 330395.94 | M5: Available
A6: B1-GF-04 | B6: Luxury Fashion | C6: Ground | D6: 131.67 | E6: 3000 | F6: =IF(OR(D6="",E6=""),"",D6*E6) -> 395010 | G6: 51.97 | H6: 750 | I6: =H6*G6 -> 38977.5 | J6: =I6+F6 -> 433987.5 | K6: 2500 | L6: =IF(OR(D6="",K6=""),"",D6*K6) -> 329175 | M6: Reserved
A7: B1-GF-05 | B7: Luxury Fashion | C7: Ground | D7: 195.0312 | E7: 2000 | F7: =IF(OR(D7="",E7=""),"",D7*E7) -> 390062.4 | G7: 47.28 | H7: 750 | I7: =H7*G7 -> 35460 | J7: =I7+F7 -> 425522.4 | K7: 1550 | L7: =IF(OR(D7="",K7=""),"",D7*K7) -> 302298.36 | M7: Negotiated
A8: B1-GF-06 | B8: Luxury Fashion | C8: Ground | D8: 193.0096 | E8: 2250 | F8: =IF(OR(D8="",E8=""),"",D8*E8) -> 434271.6 | G8: 35 | H8: 750 | I8: =H8*G8 -> 26250 | J8: =I8+F8 -> 460521.6 | L8: =IF(OR(D8="",K8=""),"",D8*K8)
A9: B1-GF-07 | B9: Luxury Fashion | C9: Ground | D9: 132.335 | E9: 3000 | F9: =IF(OR(D9="",E9=""),"",D9*E9) -> 397005 | G9: 49.2 | H9: 750 | I9: =H9*G9 -> 36900 | J9: =I9+F9 -> 433905 | L9: =IF(OR(D9="",K9=""),"",D9*K9)
A10: B1-GF-08 | B10: Luxury Fashion | C10: Ground | D10: 182.6622 | E10: 3000 | F10: =IF(OR(D10="",E10=""),"",D10*E10) -> 547986.6 | G10: 54.69 | H10: 750 | I10: =H10*G10 -> 41017.5 | J10: =I10+F10 -> 589004.1 | L10: =IF(OR(D10="",K10=""),"",D10*K10)
A11: B1-GF-09 | B11: Luxury Fashion | C11: Ground | D11: 140.2884 | E11: 3000 | F11: =IF(OR(D11="",E11=""),"",D11*E11) -> 420865.2 | G11: 54.27 | H11: 750 | I11: =H11*G11 -> 40702.5 | J11: =I11+F11 -> 461567.7 | L11: =IF(OR(D11="",K11=""),"",D11*K11)
A12: B1-GF-10 | B12: Luxury Fashion | C12: Ground | D12: 437.2907 | E12: 2500 | F12: =IF(OR(D12="",E12=""),"",D12*E12) -> 1093226.8 | G12: 325.97 | H12: 750 | I12: =H12*G12 -> 244477.5 | J12: =I12+F12 -> 1337704.2 | L12: =IF(OR(D12="",K12=""),"",D12*K12)
A13: B1-GF-11 | B13: F&B | C13: Ground | D13: 101.1465 | E13: 2250 | F13: =IF(OR(D13="",E13=""),"",D13*E13) -> 227579.62 | H13: 600 | I13: =H13*G13 -> 0 | J13: =I13+F13 -> 227579.62 | L13: =IF(OR(D13="",K13=""),"",D13*K13)
A14: B1-GF-12 | B14: F&B | C14: Ground | D14: 113.449 | E14: 2250 | F14: =IF(OR(D14="",E14=""),"",D14*E14) -> 255260.25 | G14: 125.5 | H14: 750 | I14: =H14*G14 -> 94125 | J14: =I14+F14 -> 349385.25 | L14: =IF(OR(D14="",K14=""),"",D14*K14)
A15: B1-GF-13 | B15: F&B | C15: Ground | D15: 166.2899 | E15: 2000 | F15: =IF(OR(D15="",E15=""),"",D15*E15) -> 332579.8 | G15: 125.03 | H15: 700 | I15: =H15*G15 -> 87521 | J15: =I15+F15 -> 420100.8 | L15: =IF(OR(D15="",K15=""),"",D15*K15)
A16: B1-GF-14 | B16: Storage | C16: Ground | D16: 75.1051 | E16: 600 | F16: =IF(OR(D16="",E16=""),"",D16*E16) -> 45063.06 | H16: 600 | I16: =H16*G16 -> 0 | J16: =I16+F16 -> 45063.06 | L16: =IF(OR(D16="",K16=""),"",D16*K16)
A17: B1-GF-15 | B17: Storage | C17: Ground | D17: 70.3969 | E17: 600 | F17: =IF(OR(D17="",E17=""),"",D17*E17) -> 42238.14 | H17: 600 | I17: =H17*G17 -> 0 | J17: =I17+F17 -> 42238.14 | L17: =IF(OR(D17="",K17=""),"",D17*K17)
A18: B1-GF-16 | B18: Storage | C18: Ground | D18: 66.9389 | E18: 600 | F18: =IF(OR(D18="",E18=""),"",D18*E18) -> 40163.34 | H18: 600 | I18: =H18*G18 -> 0 | J18: =I18+F18 -> 40163.34 | L18: =IF(OR(D18="",K18=""),"",D18*K18)
A19: B1-GF-17 | B19: Storage | C19: Ground | D19: 70.357 | E19: 600 | F19: =IF(OR(D19="",E19=""),"",D19*E19) -> 42214.2 | H19: 600 | I19: =H19*G19 -> 0 | J19: =I19+F19 -> 42214.2 | L19: =IF(OR(D19="",K19=""),"",D19*K19)
A20: B1-GF-18 | B20: Storage | C20: Ground | D20: 67.5374 | E20: 600 | F20: =IF(OR(D20="",E20=""),"",D20*E20) -> 40522.44 | H20: 600 | I20: =H20*G20 -> 0 | J20: =I20+F20 -> 40522.44 | L20: =IF(OR(D20="",K20=""),"",D20*K20)
A21: B1-GF-19 | B21: Storage | C21: Ground | D21: 76.1824 | E21: 600 | F21: =IF(OR(D21="",E21=""),"",D21*E21) -> 45709.44 | H21: 600 | I21: =H21*G21 -> 0 | J21: =I21+F21 -> 45709.44 | L21: =IF(OR(D21="",K21=""),"",D21*K21)
A22: B1-GF-20 | B22: Storage | C22: Ground | D22: 81.5556 | E22: 600 | F22: =IF(OR(D22="",E22=""),"",D22*E22) -> 48933.36 | H22: 600 | I22: =H22*G22 -> 0 | J22: =I22+F22 -> 48933.36 | L22: =IF(OR(D22="",K22=""),"",D22*K22)
A23: B1-GF-21 | B23: Storage | C23: Ground | D23: 100.5879 | E23: 600 | F23: =IF(OR(D23="",E23=""),"",D23*E23) -> 60352.74 | H23: 600 | I23: =H23*G23 -> 0 | J23: =I23+F23 -> 60352.74 | L23: =IF(OR(D23="",K23=""),"",D23*K23)
A24: B1-GF-22 | B24: KIOSK | C24: Ground | D24: 39.368 | E24: 2800 | F24: =IF(OR(D24="",E24=""),"",D24*E24) -> 110230.4 | H24: 600 | I24: =H24*G24 -> 0 | J24: =I24+F24 -> 110230.4 | L24: =IF(OR(D24="",K24=""),"",D24*K24)
A25: B1-GF-23 | B25: KIOSK | C25: Ground | D25: 39.9 | E25: 2800 | F25: =IF(OR(D25="",E25=""),"",D25*E25) -> 111720 | H25: 600 | I25: =H25*G25 -> 0 | J25: =I25+F25 -> 111720 | L25: =IF(OR(D25="",K25=""),"",D25*K25)
A26: B1-GF-24 | B26: KIOSK | C26: Ground | D26: 40.2458 | E26: 2800 | F26: =IF(OR(D26="",E26=""),"",D26*E26) -> 112688.24 | H26: 600 | I26: =H26*G26 -> 0 | J26: =I26+F26 -> 112688.24 | L26: =IF(OR(D26="",K26=""),"",D26*K26)
A27: B1-GF-25 | B27: KIOSK | C27: Ground | D27: 36.3489 | E27: 2800 | F27: =IF(OR(D27="",E27=""),"",D27*E27) -> 101776.92 | H27: 600 | I27: =H27*G27 -> 0 | J27: =I27+F27 -> 101776.92 | L27: =IF(OR(D27="",K27=""),"",D27*K27)
... A36: B1-GF-34 | B36: KIOSK | C36: Ground | D36: 36.1095 | E36: 2000 | F36: =IF(OR(D36="",E36=""),"",D36*E36) -> 72219 | H36: 600 | I36: =H36*G36 -> 0 | J36: =I36+F36 -> 72219 | L36: =IF(OR(D36="",K36=""),"",D36*K36)
A37: B1-GF-35 | B37: F&B | C37: Ground | D37: 227.7625 | E37: 2200 | F37: =IF(OR(D37="",E37=""),"",D37*E37) -> 501077.5 | G37: =92.48+57.4+125.4 -> 275.28 | H37: 750 | I37: =H37*G37 -> 206460 | J37: =I37+F37 -> 707537.5 | L37: =IF(OR(D37="",K37=""),"",D37*K37) | M37: موجره | N37: CHECK MEP
A38: B1-GF-36 | B38: F&B | C38: Ground | D38: 225.169 | E38: 2300 | F38: =IF(OR(D38="",E38=""),"",D38*E38) -> 517888.7 | G38: 158.2 | H38: 750 | I38: =H38*G38 -> 118650 | J38: =I38+F38 -> 636538.7 | L38: =IF(OR(D38="",K38=""),"",D38*K38)
A39: B1-GF-37 | B39: F&B | C39: Ground | D39: 281.6275 | E39: 2300 | F39: =IF(OR(D39="",E39=""),"",D39*E39) -> 647743.25 | G39: 244.1 | H39: 750 | I39: =H39*G39 -> 183075 | J39: =I39+F39 -> 830818.25 | L39: =IF(OR(D39="",K39=""),"",D39*K39)
A40: B1-GF-38 | B40: F&B | C40: Ground | D40: 271.32 | E40: 2000 | F40: =IF(OR(D40="",E40=""),"",D40*E40) -> 542640 | G40: 110.69 | H40: 750 | I40: =H40*G40 -> 83017.5 | J40: =I40+F40 -> 625657.5 | L40: =IF(OR(D40="",K40=""),"",D40*K40)
A41: B1-GF-39 | B41: Kids Entertainment | C41: Ground | D41: 348.194 | E41: 1750 | F41: =IF(OR(D41="",E41=""),"",D41*E41) -> 609339.5 | G41: 279.73 | H41: 750 | I41: =H41*G41 -> 209797.5 | J41: =I41+F41 -> 819137 | L41: =IF(OR(D41="",K41=""),"",D41*K41)
A42: B1-GF-40 | B42: F&B | C42: Ground | D42: 197.9572 | E42: 2500 | F42: =IF(OR(D42="",E42=""),"",D42*E42) -> 494893 | G42: =80.15+132.7 -> 212.85 | H42: 750 | I42: =H42*G42 -> 159637.5 | J42: =I42+F42 -> 654530.5 | L42: =IF(OR(D42="",K42=""),"",D42*K42)
A43: B1-GF-41 | B43: Sephora | C43: Ground | D43: 399.9842 | E43: 2200 | F43: =IF(OR(D43="",E43=""),"",D43*E43) -> 879965.24 | G43: =322.29+197.9 -> 520.19 | H43: 750 | I43: =H43*G43 -> 390142.5 | J43: =I43+F43 -> 1270107.7 | L43: =IF(OR(D43="",K43=""),"",D43*K43)
A44: B2-GF-01 | B44: F&B | C44: Ground | D44: 230.8348 | E44: 2000 | F44: =IF(OR(D44="",E44=""),"",D44*E44) -> 461669.6 | G44: 300 | H44: 750 | I44: =H44*G44 -> 225000 | J44: =I44+F44 -> 686669.6 | L44: =IF(OR(D44="",K44=""),"",D44*K44)
A45: B2-GF-02 | B45: F&B | C45: Ground | D45: 217.1225 | E45: 2100 | F45: =IF(OR(D45="",E45=""),"",D45*E45) -> 455957.25 | G45: 78.63 | H45: 750 | I45: =H45*G45 -> 58972.5 | J45: =I45+F45 -> 514929.75 | L45: =IF(OR(D45="",K45=""),"",D45*K45)
A46: B2-GF-03 | B46: Huqqabaz | C46: Ground | D46: 615.1649 | E46: 2000 | F46: =IF(OR(D46="",E46=""),"",D46*E46) -> 1230329.8 | G46: =320.49+179.9 -> 500.39 | H46: 750 | I46: =H46*G46 -> 375292.5 | J46: =I46+F46 -> 1605622.3 | L46: =IF(OR(D46="",K46=""),"",D46*K46)
A47: B2-GF-04 | B47: F&B | C47: Ground | D47: 107.3177 | E47: 2500 | F47: =IF(OR(D47="",E47=""),"",D47*E47) -> 268294.25 | G47: 59.58 | H47: 750 | I47: =H47*G47 -> 44685 | J47: =I47+F47 -> 312979.25 | L47: =IF(OR(D47="",K47=""),"",D47*K47)
A48: B2-GF-05 | B48: F&B | C48: Ground | D48: 138.5328 | E48: 2800 | F48: =IF(OR(D48="",E48=""),"",D48*E48) -> 387891.84 | G48: 61.55 | H48: 750 | I48: =H48*G48 -> 46162.5 | J48: =I48+F48 -> 434054.34 | L48: =IF(OR(D48="",K48=""),"",D48*K48)
...
